<sdf version='1.4'>
  <model name='kinova_kg3'>
    <link name='jaco_link_hand'>
      <pose>0 0 0 0 -0 0</pose>
      <inertial>
        <pose>-0.000227691 0.00425469 0.0759514 0 -0 0</pose>
        <mass>0.49</mass>
        <inertia>
          <ixx>0.000215057</ixx>
          <ixy>1.82062e-08</ixy>
          <ixz>1.11116e-07</ixz>
          <iyy>0.00018746</iyy>
          <iyz>1.20191e-06</iyz>
          <izz>0.000158164</izz>
        </inertia>
      </inertial>
      <collision name='jaco_link_hand_collision'>
        <pose>0 0 0 0 -0 0</pose>
        <geometry>
          <mesh>
            <scale>1 1 1</scale>
            <uri>model://kinova_kg3/meshes/jaco_link_hand.STL</uri>
          </mesh>
        </geometry>
        <surface>
          <contact>
            <ode/>
          </contact>
          <friction>
            <ode/>
          </friction>
        </surface>
      </collision>
      <visual name='jaco_link_hand_visual'>
        <pose>0 0 0 0 -0 0</pose>
        <geometry>
          <mesh>
            <scale>1 1 1</scale>
            <uri>model://kinova_kg3/meshes/jaco_link_hand.STL</uri>
          </mesh>
        </geometry>
      </visual>
      <gravity>1</gravity>
      <velocity_decay>
        <linear>0</linear>
        <angular>0</angular>
      </velocity_decay>
      <self_collide>0</self_collide>
    </link>
    <link name='jaco_link_finger_1'>
      <pose>0.00228309 -0.0312567 0.11443 1.57925 -0.980345 -1.60227</pose>
      <inertial>
        <pose>0.0208281 -0.00622581 -1.06167e-07 0 -0 0</pose>
        <mass>0.05</mass>
        <inertia>
          <ixx>1.04332e-06</ixx>
          <ixy>1.35201e-07</ixy>
          <ixz>-1.63982e-11</ixz>
          <iyy>2.40167e-06</iyy>
          <iyz>-2.0631e-12</iyz>
          <izz>2.18919e-06</izz>
        </inertia>
      </inertial>
      <collision name='jaco_link_finger_1_collision'>
        <pose>0 0 0 0 -0 0</pose>
        <geometry>
          <mesh>
            <scale>1 1 1</scale>
            <uri>model://kinova_kg3/meshes/jaco_link_finger_2.STL</uri>
          </mesh>
        </geometry>
        <surface>
          <contact>
            <ode>
              <kp>1e+06</kp>
              <kd>1</kd>
            </ode>
          </contact>
          <friction>
            <ode>
              <mu>500</mu>
              <mu2>500</mu2>
            </ode>
          </friction>
        </surface>
      </collision>
      <visual name='jaco_link_finger_1_visual'>
        <pose>0 0 0 0 -0 0</pose>
        <geometry>
          <mesh>
            <scale>1 1 1</scale>
            <uri>model://kinova_kg3/meshes/jaco_link_finger_2.STL</uri>
          </mesh>
        </geometry>
      </visual>
      <gravity>0</gravity>
      <velocity_decay>
        <linear>0</linear>
        <angular>0</angular>
      </velocity_decay>
      <self_collide>0</self_collide>
    </link>
    <joint name='jaco_joint_finger_1' type='revolute'>
      <child>jaco_link_finger_1</child>
      <parent>jaco_link_hand</parent>
      <axis>
        <xyz>-0.99969 0.0244463 -0.004708</xyz>
        <limit>
          <lower>0</lower>
          <upper>0.872665</upper>
          <effort>30</effort>
          <velocity>5</velocity>
        </limit>
        <dynamics/>
      </axis>
      <physics>
        <provide_feedback>1</provide_feedback>
        <ode>
          <provide_feedback>1</provide_feedback>
          <fudge_factor>1</fudge_factor>
          <limit>
            <cfm>0</cfm>
            <erp>0.2</erp>
          </limit>
        </ode>
      </physics>
    </joint>
    <link name='jaco_link_finger_tip_1'>
      <pose>0.00151043 -0.0557978 0.151066 1.57925 -0.980345 -1.60227</pose>
      <inertial>
        <pose>0.0140499 -0.00605434 2.02852e-07 0 -0 0</pose>
        <mass>0.03</mass>
        <inertia>
          <ixx>6.83326e-07</ixx>
          <ixy>-2.81123e-07</ixy>
          <ixz>-7.46392e-12</ixz>
          <iyy>2.46927e-06</iyy>
          <iyz>1.87459e-11</iyz>
          <izz>2.36577e-06</izz>
        </inertia>
      </inertial>
      <collision name='jaco_link_finger_tip_1_collision'>
        <pose>0 0 0 0 -0 0</pose>
        <geometry>
          <mesh>
            <scale>1 1 1</scale>
            <uri>model://kinova_kg3/meshes/jaco_link_finger_tip_2.STL</uri>
          </mesh>
        </geometry>
        <surface>
          <contact>
            <ode>
              <kp>1e+07</kp>
              <kd>1</kd>
            </ode>
          </contact>
          <friction>
            <ode>
              <mu>500</mu>
              <mu2>500</mu2>
            </ode>
          </friction>
        </surface>
      </collision>
      <visual name='jaco_link_finger_tip_1_visual'>
        <pose>0 0 0 0 -0 0</pose>
        <geometry>
          <mesh>
            <scale>1 1 1</scale>
            <uri>model://kinova_kg3/meshes/jaco_link_finger_tip_2.STL</uri>
          </mesh>
        </geometry>
      </visual>
      <gravity>0</gravity>
      <velocity_decay>
        <linear>0</linear>
        <angular>0</angular>
      </velocity_decay>
      <self_collide>0</self_collide>
      <sensor name='jaco_link_finger_tip_1_contact_sensor' type='contact'>
        <update_rate>100</update_rate>
        <contact>
          <collision>jaco_link_finger_tip_1_collision</collision>
          <topic>__default_topic__</topic>
        </contact>
        <plugin name='jaco_link_finger_tip_1_gazebo_ros_bumper_controller' filename='libgazebo_ros_bumper.so'>
          <alwaysOn>true</alwaysOn>
          <frameName>jaco_link_finger_tip_1</frameName>
          <updateRate>100.0</updateRate>
          <bumperTopicName>jaco_link_finger_tip_1_bumper</bumperTopicName>
        </plugin>
      </sensor>
    </link>
    <joint name='jaco_joint_finger_tip_1' type='revolute'>
      <child>jaco_link_finger_tip_1</child>
      <parent>jaco_link_finger_1</parent>
      <axis>
        <xyz>-0.99969 0.0244463 -0.004708</xyz>
        <limit>
          <lower>0</lower>
          <upper>0.872665</upper>
          <effort>30</effort>
          <velocity>5</velocity>
        </limit>
        <dynamics/>
      </axis>
      <physics>
        <provide_feedback>1</provide_feedback>
        <ode>
          <provide_feedback>1</provide_feedback>
          <fudge_factor>1</fudge_factor>
          <limit>
            <cfm>0</cfm>
            <erp>0.2</erp>
          </limit>
        </ode>
      </physics>
    </joint>
    <link name='jaco_link_finger_2'>
      <pose>0.0216845 0.0270991 0.114669 1.56248 -0.979965 1.39417</pose>
      <inertial>
        <pose>0.0208281 -0.00622581 -1.06167e-07 0 -0 0</pose>
        <mass>0.05</mass>
        <inertia>
          <ixx>1.04332e-06</ixx>
          <ixy>1.35201e-07</ixy>
          <ixz>-1.63982e-11</ixz>
          <iyy>2.40167e-06</iyy>
          <iyz>-2.0631e-12</iyz>
          <izz>2.18919e-06</izz>
        </inertia>
      </inertial>
      <collision name='jaco_link_finger_2_collision'>
        <pose>0 0 0 0 -0 0</pose>
        <geometry>
          <mesh>
            <scale>1 1 1</scale>
            <uri>model://kinova_kg3/meshes/jaco_link_finger_2.STL</uri>
          </mesh>
        </geometry>
        <surface>
          <contact>
            <ode>
              <kp>1e+06</kp>
              <kd>1</kd>
            </ode>
          </contact>
          <friction>
            <ode>
              <mu>500</mu>
              <mu2>500</mu2>
            </ode>
          </friction>
        </surface>
      </collision>
      <visual name='jaco_link_finger_2_visual'>
        <pose>0 0 0 0 -0 0</pose>
        <geometry>
          <mesh>
            <scale>1 1 1</scale>
            <uri>model://kinova_kg3/meshes/jaco_link_finger_2.STL</uri>
          </mesh>
        </geometry>
      </visual>
      <gravity>0</gravity>
      <velocity_decay>
        <linear>0</linear>
        <angular>0</angular>
      </velocity_decay>
      <self_collide>0</self_collide>
    </link>
    <joint name='jaco_joint_finger_2' type='revolute'>
      <child>jaco_link_finger_2</child>
      <parent>jaco_link_hand</parent>
      <axis>
        <xyz>0.983195 -0.1825 0.00463032</xyz>
        <limit>
          <lower>0</lower>
          <upper>0.872665</upper>
          <effort>30</effort>
          <velocity>5</velocity>
        </limit>
        <dynamics/>
      </axis>
      <physics>
        <provide_feedback>1</provide_feedback>
        <ode>
          <provide_feedback>1</provide_feedback>
          <fudge_factor>1</fudge_factor>
          <limit>
            <cfm>0</cfm>
            <erp>0.2</erp>
          </limit>
        </ode>
      </physics>
    </joint>
    <link name='jaco_link_finger_tip_2'>
      <pose>0.0260012 0.0512841 0.151295 1.56248 -0.979965 1.39417</pose>
      <inertial>
        <pose>0.0140499 -0.00605434 2.02852e-07 0 -0 0</pose>
        <mass>0.03</mass>
        <inertia>
          <ixx>6.83326e-07</ixx>
          <ixy>-2.81123e-07</ixy>
          <ixz>-7.46392e-12</ixz>
          <iyy>2.46927e-06</iyy>
          <iyz>1.87459e-11</iyz>
          <izz>2.36577e-06</izz>
        </inertia>
      </inertial>
      <collision name='jaco_link_finger_tip_2_collision'>
        <pose>0 0 0 0 -0 0</pose>
        <geometry>
          <mesh>
            <scale>1 1 1</scale>
            <uri>model://kinova_kg3/meshes/jaco_link_finger_tip_2.STL</uri>
          </mesh>
        </geometry>
        <surface>
          <contact>
            <ode>
              <kp>1e+07</kp>
              <kd>1</kd>
            </ode>
          </contact>
          <friction>
            <ode>
              <mu>500</mu>
              <mu2>500</mu2>
            </ode>
          </friction>
        </surface>
      </collision>
      <visual name='jaco_link_finger_tip_2_visual'>
        <pose>0 0 0 0 -0 0</pose>
        <geometry>
          <mesh>
            <scale>1 1 1</scale>
            <uri>model://kinova_kg3/meshes/jaco_link_finger_tip_2.STL</uri>
          </mesh>
        </geometry>
      </visual>
      <gravity>0</gravity>
      <velocity_decay>
        <linear>0</linear>
        <angular>0</angular>
      </velocity_decay>
      <self_collide>0</self_collide>
      <sensor name='jaco_link_finger_tip_2_contact_sensor' type='contact'>
        <update_rate>100</update_rate>
        <contact>
          <collision>jaco_link_finger_tip_2_collision</collision>
          <topic>__default_topic__</topic>
        </contact>
        <plugin name='jaco_link_finger_tip_2_gazebo_ros_bumper_controller' filename='libgazebo_ros_bumper.so'>
          <alwaysOn>true</alwaysOn>
          <frameName>jaco_link_finger_tip_2</frameName>
          <updateRate>100.0</updateRate>
          <bumperTopicName>jaco_link_finger_tip_2_bumper</bumperTopicName>
        </plugin>
      </sensor>
    </link>
    <joint name='jaco_joint_finger_tip_2' type='revolute'>
      <child>jaco_link_finger_tip_2</child>
      <parent>jaco_link_finger_2</parent>
      <axis>
        <xyz>0.983195 -0.1825 0.00463032</xyz>
        <limit>
          <lower>0</lower>
          <upper>0.872665</upper>
          <effort>30</effort>
          <velocity>5</velocity>
        </limit>
        <dynamics/>
      </axis>
      <physics>
        <provide_feedback>1</provide_feedback>
        <ode>
          <provide_feedback>1</provide_feedback>
          <fudge_factor>1</fudge_factor>
          <limit>
            <cfm>0</cfm>
            <erp>0.2</erp>
          </limit>
        </ode>
      </physics>
    </joint>
    <link name='jaco_link_finger_3'>
      <pose>-0.0228266 0.0270473 0.11446 1.56251 -0.978235 1.76353</pose>
      <inertial>
        <pose>0.0208281 -0.00622581 -1.06167e-07 0 -0 0</pose>
        <mass>0.05</mass>
        <inertia>
          <ixx>1.04332e-06</ixx>
          <ixy>1.35201e-07</ixy>
          <ixz>-1.63982e-11</ixz>
          <iyy>2.40167e-06</iyy>
          <iyz>-2.0631e-12</iyz>
          <izz>2.18919e-06</izz>
        </inertia>
      </inertial>
      <collision name='jaco_link_finger_3_collision'>
        <pose>0 0 0 0 -0 0</pose>
        <geometry>
          <mesh>
            <scale>1 1 1</scale>
            <uri>model://kinova_kg3/meshes/jaco_link_finger_2.STL</uri>
          </mesh>
        </geometry>
        <surface>
          <contact>
            <ode>
              <kp>1e+06</kp>
              <kd>1</kd>
            </ode>
          </contact>
          <friction>
            <ode>
              <mu>500</mu>
              <mu2>500</mu2>
            </ode>
          </friction>
        </surface>
      </collision>
      <visual name='jaco_link_finger_3_visual'>
        <pose>0 0 0 0 -0 0</pose>
        <geometry>
          <mesh>
            <scale>1 1 1</scale>
            <uri>model://kinova_kg3/meshes/jaco_link_finger_2.STL</uri>
          </mesh>
        </geometry>
      </visual>
      <gravity>0</gravity>
      <velocity_decay>
        <linear>0</linear>
        <angular>0</angular>
      </velocity_decay>
      <self_collide>0</self_collide>
    </link>
    <joint name='jaco_joint_finger_3' type='revolute'>
      <child>jaco_link_finger_3</child>
      <parent>jaco_link_hand</parent>
      <axis>
        <xyz>0.982767 0.184788 0.00462831</xyz>
        <limit>
          <lower>0</lower>
          <upper>0.872665</upper>
          <effort>30</effort>
          <velocity>5</velocity>
        </limit>
        <dynamics/>
      </axis>
      <physics>
        <provide_feedback>1</provide_feedback>
        <ode>
          <provide_feedback>1</provide_feedback>
          <fudge_factor>1</fudge_factor>
          <limit>
            <cfm>0</cfm>
            <erp>0.2</erp>
          </limit>
        </ode>
      </physics>
    </joint>
    <link name='jaco_link_finger_tip_3'>
      <pose>-0.0275444 0.0512218 0.151043 1.56251 -0.978235 1.76353</pose>
      <inertial>
        <pose>0.0140499 -0.00605434 2.02852e-07 0 -0 0</pose>
        <mass>0.03</mass>
        <inertia>
          <ixx>6.83326e-07</ixx>
          <ixy>-2.81123e-07</ixy>
          <ixz>-7.46392e-12</ixz>
          <iyy>2.46927e-06</iyy>
          <iyz>1.87459e-11</iyz>
          <izz>2.36577e-06</izz>
        </inertia>
      </inertial>
      <collision name='jaco_link_finger_tip_3_collision'>
        <pose>0 0 0 0 -0 0</pose>
        <geometry>
          <mesh>
            <scale>1 1 1</scale>
            <uri>model://kinova_kg3/meshes/jaco_link_finger_tip_2.STL</uri>
          </mesh>
        </geometry>
        <surface>
          <contact>
            <ode>
              <kp>1e+07</kp>
              <kd>1</kd>
            </ode>
          </contact>
          <friction>
            <ode>
              <mu>500</mu>
              <mu2>500</mu2>
            </ode>
          </friction>
        </surface>
      </collision>
      <visual name='jaco_link_finger_tip_3_visual'>
        <pose>0 0 0 0 -0 0</pose>
        <geometry>
          <mesh>
            <scale>1 1 1</scale>
            <uri>model://kinova_kg3/meshes/jaco_link_finger_tip_2.STL</uri>
          </mesh>
        </geometry>
      </visual>
      <gravity>0</gravity>
      <velocity_decay>
        <linear>0</linear>
        <angular>0</angular>
      </velocity_decay>
      <self_collide>0</self_collide>
      <sensor name='jaco_link_finger_tip_3_contact_sensor' type='contact'>
        <update_rate>100</update_rate>
        <contact>
          <collision>jaco_link_finger_tip_3_collision</collision>
          <topic>__default_topic__</topic>
        </contact>
        <plugin name='jaco_link_finger_tip_3_gazebo_ros_bumper_controller' filename='libgazebo_ros_bumper.so'>
          <alwaysOn>true</alwaysOn>
          <frameName>jaco_link_finger_tip_3</frameName>
          <updateRate>100.0</updateRate>
          <bumperTopicName>jaco_link_finger_tip_3_bumper</bumperTopicName>
        </plugin>
      </sensor>
    </link>
    <joint name='jaco_joint_finger_tip_3' type='revolute'>
      <child>jaco_link_finger_tip_3</child>
      <parent>jaco_link_finger_3</parent>
      <axis>
        <xyz>0.982767 0.184788 0.00462831</xyz>
        <limit>
          <lower>0</lower>
          <upper>0.872665</upper>
          <effort>30</effort>
          <velocity>5</velocity>
        </limit>
        <dynamics/>
      </axis>
      <physics>
        <provide_feedback>1</provide_feedback>
        <ode>
          <provide_feedback>1</provide_feedback>
          <fudge_factor>1</fudge_factor>
          <limit>
            <cfm>0</cfm>
            <erp>0.2</erp>
          </limit>
        </ode>
      </physics>
    </joint>
    <plugin name='p3d_jaco_link_hand_controller' filename='libgazebo_ros_p3d.so'>
      <alwaysOn>true</alwaysOn>
      <updateRate>100.0</updateRate>
      <bodyName>jaco_link_hand</bodyName>
      <topicName>jaco_link_hand_pose_ground_truth</topicName>
      <xyzOffsets>0 0 0</xyzOffsets>
      <rpyOffsets>0 0 0</rpyOffsets>
      <gaussianNoise>0.0</gaussianNoise>
      <frameName>map</frameName>
    </plugin>
    <gripper name='kionva_kg3_grasp_hack'>
      <grasp_check>
        <attach_steps>20</attach_steps>
        <detach_steps>40</detach_steps>
        <min_contact_count>2</min_contact_count>
      </grasp_check>
      <gripper_link>jaco_link_finger_tip_1</gripper_link>
      <gripper_link>jaco_link_finger_tip_2</gripper_link>
      <gripper_link>jaco_link_finger_tip_3</gripper_link>
      <palm_link>jaco_link_hand</palm_link>
    </gripper>
    <static>0</static>
    <plugin name='gazebo_ros_control' filename='libgazebo_ros_control.so'>
      <robotNamespace>kinova_kg3</robotNamespace>
    </plugin>
  </model>
</sdf>
