<?xml version="1.0" ?>
<!-- =================================================================================== -->
<!-- |    This document was autogenerated by xacro from kinova_kg3.xacro               | -->
<!-- |    EDITING THIS FILE BY HAND IS NOT RECOMMENDED                                 | -->
<!-- =================================================================================== -->
<robot name="kinova_kg3" xmlns:xacro="http://ros.org/wiki/xacro">
  <link name="jaco_link_hand">
    <inertial>
      <origin rpy="0 0 0" xyz="-0.000227690650068603 0.0042546911231965 0.0759513725294467"/>
      <mass value="0.121634609410213"/>
      <inertia ixx="0.000215056800843909" ixy="1.82062151904145E-08" ixz="1.11116219706148E-07" iyy="0.000187460117519514" iyz="1.201905023717E-06" izz="0.000158164269231599"/>
    </inertial>
    <visual>
      <origin rpy="0 0 0" xyz="0 0 0"/>
      <geometry>
        <mesh filename="package://kinova_kg3/meshes/jaco_link_hand.STL"/>
      </geometry>
      <material name="">
        <color rgba="0.752941176470588 0.752941176470588 0.752941176470588 1"/>
      </material>
    </visual>
    <collision>
      <origin rpy="0 0 0" xyz="0 0 0"/>
      <geometry>
        <mesh filename="package://kinova_kg3/meshes/jaco_link_hand.STL"/>
      </geometry>
    </collision>
  </link>
  <joint name="jaco_joint_finger_1" type="revolute">
    <origin rpy="1.57925286601 -0.980344825914 -1.60227019088" xyz="0.00228309324473 -0.0312566848706 0.114430431187"/>
    <parent link="jaco_link_hand"/>
    <child link="jaco_link_finger_1"/>
    <limit effort="30" lower="0" upper="0.872664625997" velocity="5"/>
    <axis xyz="0 0 1"/>
  </joint>
  <link name="jaco_link_finger_1">
    <inertial>
      <origin rpy="0 0 0" xyz="0.0208280958661102 -0.00622581300157336 -1.06166677567299E-07"/>
      <mass value="0.00888493693152805"/>
      <inertia ixx="1.04331946762797E-06" ixy="1.35201064011024E-07" ixz="-1.63981636937686E-11" iyy="2.40166986344156E-06" iyz="-2.06309851527123E-12" izz="2.18918819368423E-06"/>
    </inertial>
    <visual>
      <origin rpy="0 0 0" xyz="0 0 0"/>
      <geometry>
        <mesh filename="package://kinova_kg3/meshes/jaco_link_finger_2.STL"/>
      </geometry>
      <material name="kinova_color">
        <color rgba="1 1 1 1"/>
      </material>
    </visual>
    <collision>
      <origin rpy="0 0 0" xyz="0 0 0"/>
      <geometry>
        <mesh filename="package://kinova_kg3/meshes/jaco_link_finger_2.STL"/>
      </geometry>
    </collision>
  </link>
  <link name="jaco_link_finger_tip_1">
    <inertial>
      <origin rpy="0 0 0" xyz="0.0140498893489319 -0.00605433855046034 2.02852203314789E-07"/>
      <mass value="0.0124078189139213"/>
      <inertia ixx="6.8332629760199E-07" ixy="-2.81122850352448E-07" ixz="-7.46391812800588E-12" iyy="2.46927029259255E-06" iyz="1.87459305381369E-11" izz="2.36577455894539E-06"/>
    </inertial>
    <visual>
      <origin rpy="0 0 0" xyz="0 0 0"/>
      <geometry>
        <mesh filename="package://kinova_kg3/meshes/jaco_link_finger_tip_2.STL"/>
      </geometry>
      <material name="kinova_color"/>
    </visual>
    <collision>
      <origin rpy="0 0 0" xyz="0 0 0"/>
      <geometry>
        <mesh filename="package://kinova_kg3/meshes/jaco_link_finger_tip_2.STL"/>
      </geometry>
    </collision>
  </link>
  <joint name="jaco_joint_finger_tip_1" type="revolute">
    <origin rpy="-1.11022302462516E-16 1.38777878078145E-17 -8.67361737988404E-18" xyz="0.0441021541423999 0 0"/>
    <parent link="jaco_link_finger_1"/>
    <child link="jaco_link_finger_tip_1"/>
    <limit effort="30" lower="0" upper="0.872664625997" velocity="5"/>
    <axis xyz="0 0 1"/>
  </joint>
  <joint name="jaco_joint_finger_2" type="revolute">
    <origin rpy="1.56248404081 -0.979964587179 1.39416913027" xyz="0.021684484967 0.0270991446492 0.114669378847"/>
    <parent link="jaco_link_hand"/>
    <child link="jaco_link_finger_2"/>
    <limit effort="30" lower="0" upper="0.872664625997" velocity="5"/>
    <axis xyz="0 0 1"/>
  </joint>
  <link name="jaco_link_finger_2">
    <inertial>
      <origin rpy="0 0 0" xyz="0.0208280958661102 -0.00622581300157336 -1.06166677567299E-07"/>
      <mass value="0.00888493693152805"/>
      <inertia ixx="1.04331946762797E-06" ixy="1.35201064011024E-07" ixz="-1.63981636937686E-11" iyy="2.40166986344156E-06" iyz="-2.06309851527123E-12" izz="2.18918819368423E-06"/>
    </inertial>
    <visual>
      <origin rpy="0 0 0" xyz="0 0 0"/>
      <geometry>
        <mesh filename="package://kinova_kg3/meshes/jaco_link_finger_2.STL"/>
      </geometry>
      <material name="kinova_color">
        <color rgba="1 1 1 1"/>
      </material>
    </visual>
    <collision>
      <origin rpy="0 0 0" xyz="0 0 0"/>
      <geometry>
        <mesh filename="package://kinova_kg3/meshes/jaco_link_finger_2.STL"/>
      </geometry>
    </collision>
  </link>
  <link name="jaco_link_finger_tip_2">
    <inertial>
      <origin rpy="0 0 0" xyz="0.0140498893489319 -0.00605433855046034 2.02852203314789E-07"/>
      <mass value="0.0124078189139213"/>
      <inertia ixx="6.8332629760199E-07" ixy="-2.81122850352448E-07" ixz="-7.46391812800588E-12" iyy="2.46927029259255E-06" iyz="1.87459305381369E-11" izz="2.36577455894539E-06"/>
    </inertial>
    <visual>
      <origin rpy="0 0 0" xyz="0 0 0"/>
      <geometry>
        <mesh filename="package://kinova_kg3/meshes/jaco_link_finger_tip_2.STL"/>
      </geometry>
      <material name="kinova_color"/>
    </visual>
    <collision>
      <origin rpy="0 0 0" xyz="0 0 0"/>
      <geometry>
        <mesh filename="package://kinova_kg3/meshes/jaco_link_finger_tip_2.STL"/>
      </geometry>
    </collision>
  </link>
  <joint name="jaco_joint_finger_tip_2" type="revolute">
    <origin rpy="-1.11022302462516E-16 1.38777878078145E-17 -8.67361737988404E-18" xyz="0.0441021541423999 0 0"/>
    <parent link="jaco_link_finger_2"/>
    <child link="jaco_link_finger_tip_2"/>
    <limit effort="30" lower="0" upper="0.872664625997" velocity="5"/>
    <axis xyz="0 0 1"/>
  </joint>
  <joint name="jaco_joint_finger_3" type="revolute">
    <origin rpy="1.56250901308 -0.978234931608 1.76352902216" xyz="-0.0228265816405 0.0270473381757 0.114459755558"/>
    <parent link="jaco_link_hand"/>
    <child link="jaco_link_finger_3"/>
    <limit effort="30" lower="0" upper="0.872664625997" velocity="5"/>
    <axis xyz="0 0 1"/>
  </joint>
  <link name="jaco_link_finger_3">
    <inertial>
      <origin rpy="0 0 0" xyz="0.0208280958661102 -0.00622581300157336 -1.06166677567299E-07"/>
      <mass value="0.00888493693152805"/>
      <inertia ixx="1.04331946762797E-06" ixy="1.35201064011024E-07" ixz="-1.63981636937686E-11" iyy="2.40166986344156E-06" iyz="-2.06309851527123E-12" izz="2.18918819368423E-06"/>
    </inertial>
    <visual>
      <origin rpy="0 0 0" xyz="0 0 0"/>
      <geometry>
        <mesh filename="package://kinova_kg3/meshes/jaco_link_finger_2.STL"/>
      </geometry>
      <material name="kinova_color">
        <color rgba="1 1 1 1"/>
      </material>
    </visual>
    <collision>
      <origin rpy="0 0 0" xyz="0 0 0"/>
      <geometry>
        <mesh filename="package://kinova_kg3/meshes/jaco_link_finger_2.STL"/>
      </geometry>
    </collision>
  </link>
  <link name="jaco_link_finger_tip_3">
    <inertial>
      <origin rpy="0 0 0" xyz="0.0140498893489319 -0.00605433855046034 2.02852203314789E-07"/>
      <mass value="0.0124078189139213"/>
      <inertia ixx="6.8332629760199E-07" ixy="-2.81122850352448E-07" ixz="-7.46391812800588E-12" iyy="2.46927029259255E-06" iyz="1.87459305381369E-11" izz="2.36577455894539E-06"/>
    </inertial>
    <visual>
      <origin rpy="0 0 0" xyz="0 0 0"/>
      <geometry>
        <mesh filename="package://kinova_kg3/meshes/jaco_link_finger_tip_2.STL"/>
      </geometry>
      <material name="kinova_color"/>
    </visual>
    <collision>
      <origin rpy="0 0 0" xyz="0 0 0"/>
      <geometry>
        <mesh filename="package://kinova_kg3/meshes/jaco_link_finger_tip_2.STL"/>
      </geometry>
    </collision>
  </link>
  <joint name="jaco_joint_finger_tip_3" type="revolute">
    <origin rpy="-1.11022302462516E-16 1.38777878078145E-17 -8.67361737988404E-18" xyz="0.0441021541423999 0 0"/>
    <parent link="jaco_link_finger_3"/>
    <child link="jaco_link_finger_tip_3"/>
    <limit effort="30" lower="0" upper="0.872664625997" velocity="5"/>
    <axis xyz="0 0 1"/>
  </joint>
  <joint name="jaco_joint_finger_2_inner_1" type="prismatic">
    <origin rpy="0.00485755340747 -0.307065259944 -1.75579500695" xyz="0.021398323826 0.0251800932322 0.0889963391206"/>
    <parent link="jaco_link_hand"/>
    <child link="jaco_link_finger_2_inner_1"/>
    <limit effort="30" lower="0" upper="0.1" velocity="5"/>
    <axis xyz="0 0 1"/>
  </joint>
  <link name="jaco_link_finger_2_inner_1">
    <inertial>
      <origin rpy="0 0 0" xyz="-0.00572436770874793 6.73494100814388E-05 0.00418468832978919"/>
      <mass value="0.00136881741902143"/>
      <inertia ixx="4.5324611028635E-08" ixy="-3.14487307268928E-10" ixz="-1.8524268534963E-09" iyy="2.87248019182104E-08" iyz="8.26939707217669E-10" izz="5.15648437437962E-08"/>
    </inertial>
    <visual>
      <origin rpy="0 0 0" xyz="0 0 0"/>
      <geometry>
        <mesh filename="package://kinova_kg3/meshes/jaco_link_finger_inner_1.STL"/>
      </geometry>
      <material name="">
        <color rgba="0.250980392156863 0.250980392156863 0.250980392156863 1"/>
      </material>
    </visual>
    <collision>
      <origin rpy="0 0 0" xyz="0 0 0"/>
      <geometry>
        <mesh filename="package://kinova_kg3/meshes/jaco_link_finger_inner_1.STL"/>
      </geometry>
    </collision>
  </link>
  <joint name="jaco_joint_finger_2_inner_2" type="revolute">
    <origin rpy="1.5707963267949 -1.43820400250838 -3.14159265358979" xyz="-0.00705 5.0E-05 0.0085"/>
    <parent link="jaco_link_finger_2_inner_1"/>
    <child link="jaco_link_finger_2_inner_2"/>
    <limit effort="30" lower="0" upper="0.261799387799" velocity="5"/>
    <axis xyz="0 0 -1"/>
  </joint>
  <link name="jaco_link_finger_2_inner_2">
    <inertial>
      <origin rpy="0 0 0" xyz="0.0247689341855066 -0.000547177180408435 -6.06988084993383E-05"/>
      <mass value="0.00285897614601548"/>
      <inertia ixx="4.44581970538217E-08" ixy="4.12514024853867E-10" ixz="3.49005070507017E-09" iyy="8.43547837739221E-07" iyz="-1.98061199325774E-10" izz="8.20512961827082E-07"/>
    </inertial>
    <visual>
      <origin rpy="0 0 0" xyz="0 0 0"/>
      <geometry>
        <mesh filename="package://kinova_kg3/meshes/jaco_link_finger_inner_2.STL"/>
      </geometry>
      <material name="">
        <color rgba="0.854901960784314 0.854901960784314 0.854901960784314 1"/>
      </material>
    </visual>
    <collision>
      <origin rpy="0 0 0" xyz="0 0 0"/>
      <geometry>
        <mesh filename="package://kinova_kg3/meshes/jaco_link_finger_inner_2.STL"/>
      </geometry>
    </collision>
  </link>
  <joint name="jaco_joint_finger_2_innner_3" type="revolute">
    <origin rpy="0 -1.38777878078145E-17 -6.41847686111419E-17" xyz="0.0509159367055816 0 0"/>
    <parent link="jaco_link_finger_2_inner_2"/>
    <child link="jaco_link_finger_tip_2"/>
    <limit effort="30" lower="0" upper="0.261799387799" velocity="5"/>
    <axis xyz="0 0 -1"/>
  </joint>
</robot>

