<?xml version="1.0" ?>
<!-- =================================================================================== -->
<!-- |    This document was autogenerated by xacro from kinova_kg3.xacro               | -->
<!-- |    EDITING THIS FILE BY HAND IS NOT RECOMMENDED                                 | -->
<!-- =================================================================================== -->
<robot name="kinova_kg3" xmlns:controller="http://playerstage.sourceforge.net/gazebo/xmlschema/#controller" xmlns:interface="http://playerstage.sourceforge.net/gazebo/xmlschema/#interface" xmlns:joint="http://playerstage.sourceforge.net/gazebo/xmlschema/#slider" xmlns:sensor="http://playerstage.sourceforge.net/gazebo/xmlschema/#sensor" xmlns:xacro="http://ros.org/wiki/xacro">
  <link name="jaco_link_hand">
    <inertial>
      <origin rpy="0 0 0" xyz="-0.000227690650068603 0.0042546911231965 0.0759513725294467"/>
      <mass value="0.121634609410213"/>
      <inertia ixx="0.000215056800843909" ixy="1.82062151904145E-08" ixz="1.11116219706148E-07" iyy="0.000187460117519514" iyz="1.201905023717E-06" izz="0.000158164269231599"/>
    </inertial>
    <visual>
      <origin rpy="0 0 0" xyz="0 0 0"/>
      <geometry>
        <mesh filename="package://kinova_kg3/meshes/jaco_link_hand.STL"/>
      </geometry>
      <material name="">
        <color rgba="0.752941176470588 0.752941176470588 0.752941176470588 1"/>
      </material>
    </visual>
    <collision>
      <origin rpy="0 0 0" xyz="0 0 0"/>
      <geometry>
        <mesh filename="package://kinova_kg3/meshes/jaco_link_hand.STL"/>
      </geometry>
    </collision>
  </link>
  <gazebo reference="jaco_link_hand">
    <turnGravityOff>false</turnGravityOff>
  </gazebo>
  <gazebo>
    <plugin filename="libgazebo_ros_p3d.so" name="p3d_jaco_link_hand_controller">
      <alwaysOn>true</alwaysOn>
      <updateRate>100.0</updateRate>
      <bodyName>jaco_link_hand</bodyName>
      <topicName>jaco_link_hand_pose_ground_truth</topicName>
      <xyzOffsets>0 0 0</xyzOffsets>
      <rpyOffsets>0 0 0</rpyOffsets>
      <gaussianNoise>0.0</gaussianNoise>
      <frameName>map</frameName>
    </plugin>
    <!-- a formal implementation of grasp hack in gazebo with fixed joint -->
    <gripper name="kionva_kg3_grasp_hack">
      <grasp_check>
        <attach_steps>20</attach_steps>
        <detach_steps>40</detach_steps>
        <min_contact_count>2</min_contact_count>
      </grasp_check>
      <gripper_link>jaco_link_finger_tip_1</gripper_link>
      <gripper_link>jaco_link_finger_tip_2</gripper_link>
      <gripper_link>jaco_link_finger_tip_3</gripper_link>
      <palm_link>jaco_link_hand</palm_link>
    </gripper>
  </gazebo>
  <joint name="jaco_joint_finger_1" type="revolute">
    <origin rpy="1.57925286601 -0.980344825914 -1.60227019088" xyz="0.00228309324473 -0.0312566848706 0.114430431187"/>
    <parent link="jaco_link_hand"/>
    <child link="jaco_link_finger_1"/>
    <limit effort="30" lower="0" upper="0.872664625997" velocity="5"/>
    <axis xyz="0 0 1"/>
  </joint>
  <link name="jaco_link_finger_1">
    <inertial>
      <origin rpy="0 0 0" xyz="0.0208280958661102 -0.00622581300157336 -1.06166677567299E-07"/>
      <mass value="0.00888493693152805"/>
      <inertia ixx="1.04331946762797E-06" ixy="1.35201064011024E-07" ixz="-1.63981636937686E-11" iyy="2.40166986344156E-06" iyz="-2.06309851527123E-12" izz="2.18918819368423E-06"/>
    </inertial>
    <visual>
      <origin rpy="0 0 0" xyz="0 0 0"/>
      <geometry>
        <mesh filename="package://kinova_kg3/meshes/jaco_link_finger_2.STL"/>
      </geometry>
      <material name="kinova_color">
        <color rgba="1 1 1 1"/>
      </material>
    </visual>
    <collision>
      <origin rpy="0 0 0" xyz="0 0 0"/>
      <geometry>
        <mesh filename="package://kinova_kg3/meshes/jaco_link_finger_2.STL"/>
      </geometry>
    </collision>
  </link>
  <link name="jaco_link_finger_tip_1">
    <inertial>
      <origin rpy="0 0 0" xyz="0.0140498893489319 -0.00605433855046034 2.02852203314789E-07"/>
      <mass value="0.0124078189139213"/>
      <inertia ixx="6.8332629760199E-07" ixy="-2.81122850352448E-07" ixz="-7.46391812800588E-12" iyy="2.46927029259255E-06" iyz="1.87459305381369E-11" izz="2.36577455894539E-06"/>
    </inertial>
    <visual>
      <origin rpy="0 0 0" xyz="0 0 0"/>
      <geometry>
        <mesh filename="package://kinova_kg3/meshes/jaco_link_finger_tip_2.STL"/>
      </geometry>
      <material name="kinova_color"/>
    </visual>
    <collision>
      <origin rpy="0 0 0" xyz="0 0 0"/>
      <geometry>
        <mesh filename="package://kinova_kg3/meshes/jaco_link_finger_tip_2.STL"/>
      </geometry>
    </collision>
  </link>
  <joint name="jaco_joint_finger_tip_1" type="revolute">
    <origin rpy="-1.11022302462516E-16 1.38777878078145E-17 -8.67361737988404E-18" xyz="0.0441021541423999 0 0"/>
    <parent link="jaco_link_finger_1"/>
    <child link="jaco_link_finger_tip_1"/>
    <limit effort="30" lower="0" upper="0.872664625997" velocity="5"/>
    <axis xyz="0 0 1"/>
  </joint>
  <!-- Finger proximal digit -->
  <gazebo reference="jaco_link_finger_1">
    <turnGravityOff>true</turnGravityOff>
    <mu1 value="500.0"/>
    <mu2 value="500.0"/>
    <kp value="1000000.0"/>
    <kd value="1.0"/>
  </gazebo>
  <gazebo reference="jaco_joint_finger_1">
    <stopKd value="1.0"/>
    <stopKp value="10000000.0"/>
    <fudgeFactor value="1.0"/>
    <provideFeedback value="true"/>
  </gazebo>
  <gazebo reference="jaco_link_finger_tip_1">
    <turnGravityOff>true</turnGravityOff>
    <selfCollide>false</selfCollide>
    <sensor name="jaco_link_finger_tip_1_contact_sensor" type="contact">
      <update_rate>100.0</update_rate>
      <contact>
        <collision>jaco_link_finger_tip_1_collision</collision>
      </contact>
      <plugin filename="libgazebo_ros_bumper.so" name="jaco_link_finger_tip_1_gazebo_ros_bumper_controller">
        <alwaysOn>true</alwaysOn>
        <frameName>jaco_link_finger_tip_1</frameName>
        <updateRate>100.0</updateRate>
        <bumperTopicName>jaco_link_finger_tip_1_bumper</bumperTopicName>
      </plugin>
    </sensor>
    <mu1 value="500.0"/>
    <mu2 value="500.0"/>
    <kp value="10000000.0"/>
    <kd value="1.0"/>
  </gazebo>
  <gazebo reference="jaco_joint_finger_tip_1">
    <stopKd value="1.0"/>
    <stopKp value="10000000.0"/>
    <fudgeFactor value="1.0"/>
    <provideFeedback value="true"/>
  </gazebo>
  <joint name="jaco_joint_finger_2" type="revolute">
    <origin rpy="1.56248404081 -0.979964587179 1.39416913027" xyz="0.021684484967 0.0270991446492 0.114669378847"/>
    <parent link="jaco_link_hand"/>
    <child link="jaco_link_finger_2"/>
    <limit effort="30" lower="0" upper="0.872664625997" velocity="5"/>
    <axis xyz="0 0 1"/>
  </joint>
  <link name="jaco_link_finger_2">
    <inertial>
      <origin rpy="0 0 0" xyz="0.0208280958661102 -0.00622581300157336 -1.06166677567299E-07"/>
      <mass value="0.00888493693152805"/>
      <inertia ixx="1.04331946762797E-06" ixy="1.35201064011024E-07" ixz="-1.63981636937686E-11" iyy="2.40166986344156E-06" iyz="-2.06309851527123E-12" izz="2.18918819368423E-06"/>
    </inertial>
    <visual>
      <origin rpy="0 0 0" xyz="0 0 0"/>
      <geometry>
        <mesh filename="package://kinova_kg3/meshes/jaco_link_finger_2.STL"/>
      </geometry>
      <material name="kinova_color">
        <color rgba="1 1 1 1"/>
      </material>
    </visual>
    <collision>
      <origin rpy="0 0 0" xyz="0 0 0"/>
      <geometry>
        <mesh filename="package://kinova_kg3/meshes/jaco_link_finger_2.STL"/>
      </geometry>
    </collision>
  </link>
  <link name="jaco_link_finger_tip_2">
    <inertial>
      <origin rpy="0 0 0" xyz="0.0140498893489319 -0.00605433855046034 2.02852203314789E-07"/>
      <mass value="0.0124078189139213"/>
      <inertia ixx="6.8332629760199E-07" ixy="-2.81122850352448E-07" ixz="-7.46391812800588E-12" iyy="2.46927029259255E-06" iyz="1.87459305381369E-11" izz="2.36577455894539E-06"/>
    </inertial>
    <visual>
      <origin rpy="0 0 0" xyz="0 0 0"/>
      <geometry>
        <mesh filename="package://kinova_kg3/meshes/jaco_link_finger_tip_2.STL"/>
      </geometry>
      <material name="kinova_color"/>
    </visual>
    <collision>
      <origin rpy="0 0 0" xyz="0 0 0"/>
      <geometry>
        <mesh filename="package://kinova_kg3/meshes/jaco_link_finger_tip_2.STL"/>
      </geometry>
    </collision>
  </link>
  <joint name="jaco_joint_finger_tip_2" type="revolute">
    <origin rpy="-1.11022302462516E-16 1.38777878078145E-17 -8.67361737988404E-18" xyz="0.0441021541423999 0 0"/>
    <parent link="jaco_link_finger_2"/>
    <child link="jaco_link_finger_tip_2"/>
    <limit effort="30" lower="0" upper="0.872664625997" velocity="5"/>
    <axis xyz="0 0 1"/>
  </joint>
  <!-- Finger proximal digit -->
  <gazebo reference="jaco_link_finger_2">
    <turnGravityOff>true</turnGravityOff>
    <mu1 value="500.0"/>
    <mu2 value="500.0"/>
    <kp value="1000000.0"/>
    <kd value="1.0"/>
  </gazebo>
  <gazebo reference="jaco_joint_finger_2">
    <stopKd value="1.0"/>
    <stopKp value="10000000.0"/>
    <fudgeFactor value="1.0"/>
    <provideFeedback value="true"/>
  </gazebo>
  <gazebo reference="jaco_link_finger_tip_2">
    <turnGravityOff>true</turnGravityOff>
    <selfCollide>false</selfCollide>
    <sensor name="jaco_link_finger_tip_2_contact_sensor" type="contact">
      <update_rate>100.0</update_rate>
      <contact>
        <collision>jaco_link_finger_tip_2_collision</collision>
      </contact>
      <plugin filename="libgazebo_ros_bumper.so" name="jaco_link_finger_tip_2_gazebo_ros_bumper_controller">
        <alwaysOn>true</alwaysOn>
        <frameName>jaco_link_finger_tip_2</frameName>
        <updateRate>100.0</updateRate>
        <bumperTopicName>jaco_link_finger_tip_2_bumper</bumperTopicName>
      </plugin>
    </sensor>
    <mu1 value="500.0"/>
    <mu2 value="500.0"/>
    <kp value="10000000.0"/>
    <kd value="1.0"/>
  </gazebo>
  <gazebo reference="jaco_joint_finger_tip_2">
    <stopKd value="1.0"/>
    <stopKp value="10000000.0"/>
    <fudgeFactor value="1.0"/>
    <provideFeedback value="true"/>
  </gazebo>
  <joint name="jaco_joint_finger_3" type="revolute">
    <origin rpy="1.56250901308 -0.978234931608 1.76352902216" xyz="-0.0228265816405 0.0270473381757 0.114459755558"/>
    <parent link="jaco_link_hand"/>
    <child link="jaco_link_finger_3"/>
    <limit effort="30" lower="0" upper="0.872664625997" velocity="5"/>
    <axis xyz="0 0 1"/>
  </joint>
  <link name="jaco_link_finger_3">
    <inertial>
      <origin rpy="0 0 0" xyz="0.0208280958661102 -0.00622581300157336 -1.06166677567299E-07"/>
      <mass value="0.00888493693152805"/>
      <inertia ixx="1.04331946762797E-06" ixy="1.35201064011024E-07" ixz="-1.63981636937686E-11" iyy="2.40166986344156E-06" iyz="-2.06309851527123E-12" izz="2.18918819368423E-06"/>
    </inertial>
    <visual>
      <origin rpy="0 0 0" xyz="0 0 0"/>
      <geometry>
        <mesh filename="package://kinova_kg3/meshes/jaco_link_finger_2.STL"/>
      </geometry>
      <material name="kinova_color">
        <color rgba="1 1 1 1"/>
      </material>
    </visual>
    <collision>
      <origin rpy="0 0 0" xyz="0 0 0"/>
      <geometry>
        <mesh filename="package://kinova_kg3/meshes/jaco_link_finger_2.STL"/>
      </geometry>
    </collision>
  </link>
  <link name="jaco_link_finger_tip_3">
    <inertial>
      <origin rpy="0 0 0" xyz="0.0140498893489319 -0.00605433855046034 2.02852203314789E-07"/>
      <mass value="0.0124078189139213"/>
      <inertia ixx="6.8332629760199E-07" ixy="-2.81122850352448E-07" ixz="-7.46391812800588E-12" iyy="2.46927029259255E-06" iyz="1.87459305381369E-11" izz="2.36577455894539E-06"/>
    </inertial>
    <visual>
      <origin rpy="0 0 0" xyz="0 0 0"/>
      <geometry>
        <mesh filename="package://kinova_kg3/meshes/jaco_link_finger_tip_2.STL"/>
      </geometry>
      <material name="kinova_color"/>
    </visual>
    <collision>
      <origin rpy="0 0 0" xyz="0 0 0"/>
      <geometry>
        <mesh filename="package://kinova_kg3/meshes/jaco_link_finger_tip_2.STL"/>
      </geometry>
    </collision>
  </link>
  <joint name="jaco_joint_finger_tip_3" type="revolute">
    <origin rpy="-1.11022302462516E-16 1.38777878078145E-17 -8.67361737988404E-18" xyz="0.0441021541423999 0 0"/>
    <parent link="jaco_link_finger_3"/>
    <child link="jaco_link_finger_tip_3"/>
    <limit effort="30" lower="0" upper="0.872664625997" velocity="5"/>
    <axis xyz="0 0 1"/>
  </joint>
  <!-- Finger proximal digit -->
  <gazebo reference="jaco_link_finger_3">
    <turnGravityOff>true</turnGravityOff>
    <mu1 value="500.0"/>
    <mu2 value="500.0"/>
    <kp value="1000000.0"/>
    <kd value="1.0"/>
  </gazebo>
  <gazebo reference="jaco_joint_finger_3">
    <stopKd value="1.0"/>
    <stopKp value="10000000.0"/>
    <fudgeFactor value="1.0"/>
    <provideFeedback value="true"/>
  </gazebo>
  <gazebo reference="jaco_link_finger_tip_3">
    <turnGravityOff>true</turnGravityOff>
    <selfCollide>false</selfCollide>
    <sensor name="jaco_link_finger_tip_3_contact_sensor" type="contact">
      <update_rate>100.0</update_rate>
      <contact>
        <collision>jaco_link_finger_tip_3_collision</collision>
      </contact>
      <plugin filename="libgazebo_ros_bumper.so" name="jaco_link_finger_tip_3_gazebo_ros_bumper_controller">
        <alwaysOn>true</alwaysOn>
        <frameName>jaco_link_finger_tip_3</frameName>
        <updateRate>100.0</updateRate>
        <bumperTopicName>jaco_link_finger_tip_3_bumper</bumperTopicName>
      </plugin>
    </sensor>
    <mu1 value="500.0"/>
    <mu2 value="500.0"/>
    <kp value="10000000.0"/>
    <kd value="1.0"/>
  </gazebo>
  <gazebo reference="jaco_joint_finger_tip_3">
    <stopKd value="1.0"/>
    <stopKp value="10000000.0"/>
    <fudgeFactor value="1.0"/>
    <provideFeedback value="true"/>
  </gazebo>
  <!--
	<xacro:include filename="kinova_kg3_finger_inner.xacro" />
	<xacro:kinova_kg3_finger_inner index="2" origin_xx="0.0213983238259719" origin_yy="0.025180093232184" origin_zz="0.0889963391205734"
      origin_r="0.00485755340747217" origin_p="-0.307065259944085" origin_y="-1.75579500695222" />
-->
</robot>

